wandb: Currently logged in as: crazyboy9103. Use `wandb login --relogin` to force relogin
wandb: ERROR Error while calling W&B API: Error 1062: Duplicate entry '36808833-20220830_022153' for key 'PRIMARY' (<Response [409]>)
Thread WriterThread:
Traceback (most recent call last):
  File "/home/kwangyeongill/anaconda/envs/FedSSL/lib/python3.9/site-packages/wandb/sdk/internal/internal_util.py", line 51, in run
    self._run()
  File "/home/kwangyeongill/anaconda/envs/FedSSL/lib/python3.9/site-packages/wandb/sdk/internal/internal_util.py", line 102, in _run
    self._process(record)
  File "/home/kwangyeongill/anaconda/envs/FedSSL/lib/python3.9/site-packages/wandb/sdk/internal/internal.py", line 353, in _process
    self._wm.write(record)
  File "/home/kwangyeongill/anaconda/envs/FedSSL/lib/python3.9/site-packages/wandb/sdk/internal/writer.py", line 29, in write
    self.open()
  File "/home/kwangyeongill/anaconda/envs/FedSSL/lib/python3.9/site-packages/wandb/sdk/internal/writer.py", line 25, in open
    self._ds.open_for_write(self._settings.sync_file)
  File "/home/kwangyeongill/anaconda/envs/FedSSL/lib/python3.9/site-packages/wandb/sdk/internal/datastore.py", line 77, in open_for_write
    self._fp = open(fname, open_flags)
FileExistsError: [Errno 17] File exists: '/home/kwangyeongill/FedSSL_clean/wandb/run-20220830_022158-20220830_022153/run-20220830_022153.wandb'
wandb: ERROR Internal wandb error: file data was not synced
Traceback (most recent call last):
  File "/home/kwangyeongill/anaconda/envs/FedSSL/lib/python3.9/site-packages/wandb/sdk/wandb_init.py", line 1043, in init
    run = wi.init()
  File "/home/kwangyeongill/anaconda/envs/FedSSL/lib/python3.9/site-packages/wandb/sdk/wandb_init.py", line 711, in init
    _ = backend.interface.communicate_run_start(run_obj)
  File "/home/kwangyeongill/anaconda/envs/FedSSL/lib/python3.9/site-packages/wandb/sdk/interface/interface.py", line 234, in communicate_run_start
    result = self._communicate_run_start(run_start)
  File "/home/kwangyeongill/anaconda/envs/FedSSL/lib/python3.9/site-packages/wandb/sdk/interface/interface_shared.py", line 445, in _communicate_run_start
    result = self._communicate(rec)
  File "/home/kwangyeongill/anaconda/envs/FedSSL/lib/python3.9/site-packages/wandb/sdk/interface/interface_shared.py", line 231, in _communicate
    return self._communicate_async(rec, local=local).get(timeout=timeout)
  File "/home/kwangyeongill/anaconda/envs/FedSSL/lib/python3.9/site-packages/wandb/sdk/interface/interface_sock.py", line 58, in _communicate_async
    future = self._router.send_and_receive(rec, local=local)
  File "/home/kwangyeongill/anaconda/envs/FedSSL/lib/python3.9/site-packages/wandb/sdk/interface/router.py", line 93, in send_and_receive
    self._send_message(rec)
  File "/home/kwangyeongill/anaconda/envs/FedSSL/lib/python3.9/site-packages/wandb/sdk/interface/router_sock.py", line 35, in _send_message
    self._sock_client.send_record_communicate(record)
  File "/home/kwangyeongill/anaconda/envs/FedSSL/lib/python3.9/site-packages/wandb/sdk/lib/sock_client.py", line 145, in send_record_communicate
    self.send_server_request(server_req)
  File "/home/kwangyeongill/anaconda/envs/FedSSL/lib/python3.9/site-packages/wandb/sdk/lib/sock_client.py", line 84, in send_server_request
    self._send_message(msg)
  File "/home/kwangyeongill/anaconda/envs/FedSSL/lib/python3.9/site-packages/wandb/sdk/lib/sock_client.py", line 81, in _send_message
    self._sendall_with_error_handle(header + data)
  File "/home/kwangyeongill/anaconda/envs/FedSSL/lib/python3.9/site-packages/wandb/sdk/lib/sock_client.py", line 61, in _sendall_with_error_handle
    sent = self._sock.send(data[total_sent:])
BrokenPipeError: [Errno 32] Broken pipe
wandb: ERROR Abnormal program exit
Problem at: /home/kwangyeongill/FedSSL_clean/main.py 25 <module>
Traceback (most recent call last):
  File "/home/kwangyeongill/anaconda/envs/FedSSL/lib/python3.9/site-packages/wandb/sdk/wandb_init.py", line 1043, in init
    run = wi.init()
  File "/home/kwangyeongill/anaconda/envs/FedSSL/lib/python3.9/site-packages/wandb/sdk/wandb_init.py", line 711, in init
    _ = backend.interface.communicate_run_start(run_obj)
  File "/home/kwangyeongill/anaconda/envs/FedSSL/lib/python3.9/site-packages/wandb/sdk/interface/interface.py", line 234, in communicate_run_start
    result = self._communicate_run_start(run_start)
  File "/home/kwangyeongill/anaconda/envs/FedSSL/lib/python3.9/site-packages/wandb/sdk/interface/interface_shared.py", line 445, in _communicate_run_start
    result = self._communicate(rec)
  File "/home/kwangyeongill/anaconda/envs/FedSSL/lib/python3.9/site-packages/wandb/sdk/interface/interface_shared.py", line 231, in _communicate
    return self._communicate_async(rec, local=local).get(timeout=timeout)
  File "/home/kwangyeongill/anaconda/envs/FedSSL/lib/python3.9/site-packages/wandb/sdk/interface/interface_sock.py", line 58, in _communicate_async
    future = self._router.send_and_receive(rec, local=local)
  File "/home/kwangyeongill/anaconda/envs/FedSSL/lib/python3.9/site-packages/wandb/sdk/interface/router.py", line 93, in send_and_receive
    self._send_message(rec)
  File "/home/kwangyeongill/anaconda/envs/FedSSL/lib/python3.9/site-packages/wandb/sdk/interface/router_sock.py", line 35, in _send_message
    self._sock_client.send_record_communicate(record)
  File "/home/kwangyeongill/anaconda/envs/FedSSL/lib/python3.9/site-packages/wandb/sdk/lib/sock_client.py", line 145, in send_record_communicate
    self.send_server_request(server_req)
  File "/home/kwangyeongill/anaconda/envs/FedSSL/lib/python3.9/site-packages/wandb/sdk/lib/sock_client.py", line 84, in send_server_request
    self._send_message(msg)
  File "/home/kwangyeongill/anaconda/envs/FedSSL/lib/python3.9/site-packages/wandb/sdk/lib/sock_client.py", line 81, in _send_message
    self._sendall_with_error_handle(header + data)
  File "/home/kwangyeongill/anaconda/envs/FedSSL/lib/python3.9/site-packages/wandb/sdk/lib/sock_client.py", line 61, in _sendall_with_error_handle
    sent = self._sock.send(data[total_sent:])
BrokenPipeError: [Errno 32] Broken pipe

The above exception was the direct cause of the following exception:

Traceback (most recent call last):
  File "/home/kwangyeongill/FedSSL_clean/main.py", line 25, in <module>
    wandb_writer = wandb.init(
  File "/home/kwangyeongill/anaconda/envs/FedSSL/lib/python3.9/site-packages/wandb/sdk/wandb_init.py", line 1081, in init
    raise Exception("problem") from error_seen
Exception: problem
Error in atexit._run_exitfuncs:
Traceback (most recent call last):
  File "/home/kwangyeongill/anaconda/envs/FedSSL/lib/python3.9/site-packages/wandb/sdk/lib/sock_client.py", line 81, in _send_message
    self._sendall_with_error_handle(header + data)
  File "/home/kwangyeongill/anaconda/envs/FedSSL/lib/python3.9/site-packages/wandb/sdk/lib/sock_client.py", line 61, in _sendall_with_error_handle
    sent = self._sock.send(data[total_sent:])
BrokenPipeError: [Errno 32] Broken pipe
