wandb: Currently logged in as: crazyboy9103. Use `wandb login --relogin` to force relogin
wandb: Tracking run with wandb version 0.13.1
wandb: Run data is saved locally in /home/kwangyeongill/FedSSL_clean/wandb/run-20220810_203306-20220810_203303
wandb: Run `wandb offline` to turn off syncing.
wandb: Syncing run 20220810_203303
wandb: ‚≠êÔ∏è View project at https://wandb.ai/crazyboy9103/Fed
wandb: üöÄ View run at https://wandb.ai/crazyboy9103/Fed/runs/20220810_203303
Files already downloaded and verified
Files already downloaded and verified

 | Global Training Round : 1 |

cuda:0
cuda:1
cuda:0
cuda:1
cuda:0
cuda:1
cuda:0
cuda:1
cuda:0
cuda:1
wandb: Currently logged in as: crazyboy9103. Use `wandb login --relogin` to force relogin
wandb: Currently logged in as: crazyboy9103. Use `wandb login --relogin` to force relogin
Thread WriterThread:
Traceback (most recent call last):
  File "/home/kwangyeongill/anaconda/envs/FedSSL/lib/python3.9/site-packages/wandb/sdk/internal/internal_util.py", line 51, in run
    self._run()
  File "/home/kwangyeongill/anaconda/envs/FedSSL/lib/python3.9/site-packages/wandb/sdk/internal/internal_util.py", line 102, in _run
    self._process(record)
  File "/home/kwangyeongill/anaconda/envs/FedSSL/lib/python3.9/site-packages/wandb/sdk/internal/internal.py", line 353, in _process
    self._wm.write(record)
  File "/home/kwangyeongill/anaconda/envs/FedSSL/lib/python3.9/site-packages/wandb/sdk/internal/writer.py", line 29, in write
    self.open()
  File "/home/kwangyeongill/anaconda/envs/FedSSL/lib/python3.9/site-packages/wandb/sdk/internal/writer.py", line 25, in open
    self._ds.open_for_write(self._settings.sync_file)
  File "/home/kwangyeongill/anaconda/envs/FedSSL/lib/python3.9/site-packages/wandb/sdk/internal/datastore.py", line 77, in open_for_write
    self._fp = open(fname, open_flags)
FileExistsError: [Errno 17] File exists: '/home/kwangyeongill/FedSSL_clean/wandb/run-20220810_203414-20220810_203303/run-20220810_203303.wandb'
wandb: ERROR Internal wandb error: file data was not synced
Traceback (most recent call last):
  File "/home/kwangyeongill/anaconda/envs/FedSSL/lib/python3.9/site-packages/wandb/sdk/wandb_init.py", line 1040, in init
    wi.setup(kwargs)
  File "/home/kwangyeongill/anaconda/envs/FedSSL/lib/python3.9/site-packages/wandb/sdk/wandb_init.py", line 151, in setup
    self._wl = wandb_setup.setup()
  File "/home/kwangyeongill/anaconda/envs/FedSSL/lib/python3.9/site-packages/wandb/sdk/wandb_setup.py", line 320, in setup
    ret = _setup(settings=settings)
  File "/home/kwangyeongill/anaconda/envs/FedSSL/lib/python3.9/site-packages/wandb/sdk/wandb_setup.py", line 315, in _setup
    wl = _WandbSetup(settings=settings)
  File "/home/kwangyeongill/anaconda/envs/FedSSL/lib/python3.9/site-packages/wandb/sdk/wandb_setup.py", line 301, in __init__
    _WandbSetup._instance = _WandbSetup__WandbSetup(settings=settings, pid=pid)
  File "/home/kwangyeongill/anaconda/envs/FedSSL/lib/python3.9/site-packages/wandb/sdk/wandb_setup.py", line 114, in __init__
    self._setup()
  File "/home/kwangyeongill/anaconda/envs/FedSSL/lib/python3.9/site-packages/wandb/sdk/wandb_setup.py", line 242, in _setup
    self._setup_manager()
  File "/home/kwangyeongill/anaconda/envs/FedSSL/lib/python3.9/site-packages/wandb/sdk/wandb_setup.py", line 273, in _setup_manager
    self._manager = wandb_manager._Manager(
  File "/home/kwangyeongill/anaconda/envs/FedSSL/lib/python3.9/site-packages/wandb/sdk/wandb_manager.py", line 123, in __init__
    svc_iface._svc_connect(port=port)
  File "/home/kwangyeongill/anaconda/envs/FedSSL/lib/python3.9/site-packages/wandb/sdk/service/service_sock.py", line 31, in _svc_connect
    self._sock_client.connect(port=port)
  File "/home/kwangyeongill/anaconda/envs/FedSSL/lib/python3.9/site-packages/wandb/sdk/lib/sock_client.py", line 41, in connect
    s.connect(("localhost", port))
ConnectionRefusedError: [Errno 111] Connection refused
wandb: ERROR Abnormal program exit
Process Process-3:
Traceback (most recent call last):
  File "/home/kwangyeongill/anaconda/envs/FedSSL/lib/python3.9/site-packages/wandb/sdk/wandb_init.py", line 1040, in init
    wi.setup(kwargs)
  File "/home/kwangyeongill/anaconda/envs/FedSSL/lib/python3.9/site-packages/wandb/sdk/wandb_init.py", line 151, in setup
    self._wl = wandb_setup.setup()
  File "/home/kwangyeongill/anaconda/envs/FedSSL/lib/python3.9/site-packages/wandb/sdk/wandb_setup.py", line 320, in setup
    ret = _setup(settings=settings)
  File "/home/kwangyeongill/anaconda/envs/FedSSL/lib/python3.9/site-packages/wandb/sdk/wandb_setup.py", line 315, in _setup
    wl = _WandbSetup(settings=settings)
  File "/home/kwangyeongill/anaconda/envs/FedSSL/lib/python3.9/site-packages/wandb/sdk/wandb_setup.py", line 301, in __init__
    _WandbSetup._instance = _WandbSetup__WandbSetup(settings=settings, pid=pid)
  File "/home/kwangyeongill/anaconda/envs/FedSSL/lib/python3.9/site-packages/wandb/sdk/wandb_setup.py", line 114, in __init__
    self._setup()
  File "/home/kwangyeongill/anaconda/envs/FedSSL/lib/python3.9/site-packages/wandb/sdk/wandb_setup.py", line 242, in _setup
    self._setup_manager()
  File "/home/kwangyeongill/anaconda/envs/FedSSL/lib/python3.9/site-packages/wandb/sdk/wandb_setup.py", line 273, in _setup_manager
    self._manager = wandb_manager._Manager(
  File "/home/kwangyeongill/anaconda/envs/FedSSL/lib/python3.9/site-packages/wandb/sdk/wandb_manager.py", line 123, in __init__
    svc_iface._svc_connect(port=port)
  File "/home/kwangyeongill/anaconda/envs/FedSSL/lib/python3.9/site-packages/wandb/sdk/service/service_sock.py", line 31, in _svc_connect
    self._sock_client.connect(port=port)
  File "/home/kwangyeongill/anaconda/envs/FedSSL/lib/python3.9/site-packages/wandb/sdk/lib/sock_client.py", line 41, in connect
    s.connect(("localhost", port))
ConnectionRefusedError: [Errno 111] Connection refused

The above exception was the direct cause of the following exception:

Traceback (most recent call last):
  File "/home/kwangyeongill/anaconda/envs/FedSSL/lib/python3.9/multiprocessing/process.py", line 315, in _bootstrap
    self.run()
  File "/home/kwangyeongill/anaconda/envs/FedSSL/lib/python3.9/multiprocessing/process.py", line 108, in run
    self._target(*self._args, **self._kwargs)
  File "/home/kwangyeongill/FedSSL_clean/trainers.py", line 112, in train
    wandb_writer = wandb.init(
  File "/home/kwangyeongill/anaconda/envs/FedSSL/lib/python3.9/site-packages/wandb/sdk/wandb_init.py", line 1081, in init
    raise Exception("problem") from error_seen
Exception: problem
Traceback (most recent call last):
  File "/home/kwangyeongill/anaconda/envs/FedSSL/lib/python3.9/site-packages/wandb/sdk/wandb_init.py", line 1043, in init
    run = wi.init()
  File "/home/kwangyeongill/anaconda/envs/FedSSL/lib/python3.9/site-packages/wandb/sdk/wandb_init.py", line 711, in init
    _ = backend.interface.communicate_run_start(run_obj)
  File "/home/kwangyeongill/anaconda/envs/FedSSL/lib/python3.9/site-packages/wandb/sdk/interface/interface.py", line 234, in communicate_run_start
    result = self._communicate_run_start(run_start)
  File "/home/kwangyeongill/anaconda/envs/FedSSL/lib/python3.9/site-packages/wandb/sdk/interface/interface_shared.py", line 445, in _communicate_run_start
    result = self._communicate(rec)
  File "/home/kwangyeongill/anaconda/envs/FedSSL/lib/python3.9/site-packages/wandb/sdk/interface/interface_shared.py", line 231, in _communicate
    return self._communicate_async(rec, local=local).get(timeout=timeout)
  File "/home/kwangyeongill/anaconda/envs/FedSSL/lib/python3.9/site-packages/wandb/sdk/interface/interface_sock.py", line 58, in _communicate_async
    future = self._router.send_and_receive(rec, local=local)
  File "/home/kwangyeongill/anaconda/envs/FedSSL/lib/python3.9/site-packages/wandb/sdk/interface/router.py", line 93, in send_and_receive
    self._send_message(rec)
  File "/home/kwangyeongill/anaconda/envs/FedSSL/lib/python3.9/site-packages/wandb/sdk/interface/router_sock.py", line 35, in _send_message
    self._sock_client.send_record_communicate(record)
  File "/home/kwangyeongill/anaconda/envs/FedSSL/lib/python3.9/site-packages/wandb/sdk/lib/sock_client.py", line 145, in send_record_communicate
    self.send_server_request(server_req)
  File "/home/kwangyeongill/anaconda/envs/FedSSL/lib/python3.9/site-packages/wandb/sdk/lib/sock_client.py", line 84, in send_server_request
    self._send_message(msg)
  File "/home/kwangyeongill/anaconda/envs/FedSSL/lib/python3.9/site-packages/wandb/sdk/lib/sock_client.py", line 81, in _send_message
    self._sendall_with_error_handle(header + data)
  File "/home/kwangyeongill/anaconda/envs/FedSSL/lib/python3.9/site-packages/wandb/sdk/lib/sock_client.py", line 61, in _sendall_with_error_handle
    sent = self._sock.send(data[total_sent:])
BrokenPipeError: [Errno 32] Broken pipe
wandb: ERROR Abnormal program exit
Process Process-1:
Traceback (most recent call last):
  File "/home/kwangyeongill/anaconda/envs/FedSSL/lib/python3.9/site-packages/wandb/sdk/wandb_init.py", line 1043, in init
    run = wi.init()
  File "/home/kwangyeongill/anaconda/envs/FedSSL/lib/python3.9/site-packages/wandb/sdk/wandb_init.py", line 711, in init
    _ = backend.interface.communicate_run_start(run_obj)
  File "/home/kwangyeongill/anaconda/envs/FedSSL/lib/python3.9/site-packages/wandb/sdk/interface/interface.py", line 234, in communicate_run_start
    result = self._communicate_run_start(run_start)
  File "/home/kwangyeongill/anaconda/envs/FedSSL/lib/python3.9/site-packages/wandb/sdk/interface/interface_shared.py", line 445, in _communicate_run_start
    result = self._communicate(rec)
  File "/home/kwangyeongill/anaconda/envs/FedSSL/lib/python3.9/site-packages/wandb/sdk/interface/interface_shared.py", line 231, in _communicate
    return self._communicate_async(rec, local=local).get(timeout=timeout)
  File "/home/kwangyeongill/anaconda/envs/FedSSL/lib/python3.9/site-packages/wandb/sdk/interface/interface_sock.py", line 58, in _communicate_async
    future = self._router.send_and_receive(rec, local=local)
  File "/home/kwangyeongill/anaconda/envs/FedSSL/lib/python3.9/site-packages/wandb/sdk/interface/router.py", line 93, in send_and_receive
    self._send_message(rec)
  File "/home/kwangyeongill/anaconda/envs/FedSSL/lib/python3.9/site-packages/wandb/sdk/interface/router_sock.py", line 35, in _send_message
    self._sock_client.send_record_communicate(record)
  File "/home/kwangyeongill/anaconda/envs/FedSSL/lib/python3.9/site-packages/wandb/sdk/lib/sock_client.py", line 145, in send_record_communicate
    self.send_server_request(server_req)
  File "/home/kwangyeongill/anaconda/envs/FedSSL/lib/python3.9/site-packages/wandb/sdk/lib/sock_client.py", line 84, in send_server_request
    self._send_message(msg)
  File "/home/kwangyeongill/anaconda/envs/FedSSL/lib/python3.9/site-packages/wandb/sdk/lib/sock_client.py", line 81, in _send_message
    self._sendall_with_error_handle(header + data)
  File "/home/kwangyeongill/anaconda/envs/FedSSL/lib/python3.9/site-packages/wandb/sdk/lib/sock_client.py", line 61, in _sendall_with_error_handle
    sent = self._sock.send(data[total_sent:])
BrokenPipeError: [Errno 32] Broken pipe

The above exception was the direct cause of the following exception:

Traceback (most recent call last):
  File "/home/kwangyeongill/anaconda/envs/FedSSL/lib/python3.9/multiprocessing/process.py", line 315, in _bootstrap
    self.run()
  File "/home/kwangyeongill/anaconda/envs/FedSSL/lib/python3.9/multiprocessing/process.py", line 108, in run
    self._target(*self._args, **self._kwargs)
  File "/home/kwangyeongill/FedSSL_clean/trainers.py", line 112, in train
    wandb_writer = wandb.init(
  File "/home/kwangyeongill/anaconda/envs/FedSSL/lib/python3.9/site-packages/wandb/sdk/wandb_init.py", line 1081, in init
    raise Exception("problem") from error_seen
Exception: problem
Problem at: /home/kwangyeongill/FedSSL_clean/trainers.py 112 train
Traceback (most recent call last):
  File "/home/kwangyeongill/anaconda/envs/FedSSL/lib/python3.9/site-packages/wandb/sdk/wandb_init.py", line 1040, in init
    wi.setup(kwargs)
  File "/home/kwangyeongill/anaconda/envs/FedSSL/lib/python3.9/site-packages/wandb/sdk/wandb_init.py", line 151, in setup
    self._wl = wandb_setup.setup()
  File "/home/kwangyeongill/anaconda/envs/FedSSL/lib/python3.9/site-packages/wandb/sdk/wandb_setup.py", line 320, in setup
    ret = _setup(settings=settings)
  File "/home/kwangyeongill/anaconda/envs/FedSSL/lib/python3.9/site-packages/wandb/sdk/wandb_setup.py", line 315, in _setup
    wl = _WandbSetup(settings=settings)
  File "/home/kwangyeongill/anaconda/envs/FedSSL/lib/python3.9/site-packages/wandb/sdk/wandb_setup.py", line 301, in __init__
    _WandbSetup._instance = _WandbSetup__WandbSetup(settings=settings, pid=pid)
  File "/home/kwangyeongill/anaconda/envs/FedSSL/lib/python3.9/site-packages/wandb/sdk/wandb_setup.py", line 114, in __init__
    self._setup()
  File "/home/kwangyeongill/anaconda/envs/FedSSL/lib/python3.9/site-packages/wandb/sdk/wandb_setup.py", line 242, in _setup
    self._setup_manager()
  File "/home/kwangyeongill/anaconda/envs/FedSSL/lib/python3.9/site-packages/wandb/sdk/wandb_setup.py", line 273, in _setup_manager
    self._manager = wandb_manager._Manager(
  File "/home/kwangyeongill/anaconda/envs/FedSSL/lib/python3.9/site-packages/wandb/sdk/wandb_manager.py", line 123, in __init__
    svc_iface._svc_connect(port=port)
  File "/home/kwangyeongill/anaconda/envs/FedSSL/lib/python3.9/site-packages/wandb/sdk/service/service_sock.py", line 31, in _svc_connect
    self._sock_client.connect(port=port)
  File "/home/kwangyeongill/anaconda/envs/FedSSL/lib/python3.9/site-packages/wandb/sdk/lib/sock_client.py", line 41, in connect
    s.connect(("localhost", port))
ConnectionRefusedError: [Errno 111] Connection refused
wandb: ERROR Abnormal program exit
Process Process-4:
Traceback (most recent call last):
  File "/home/kwangyeongill/anaconda/envs/FedSSL/lib/python3.9/site-packages/wandb/sdk/wandb_init.py", line 1040, in init
    wi.setup(kwargs)
  File "/home/kwangyeongill/anaconda/envs/FedSSL/lib/python3.9/site-packages/wandb/sdk/wandb_init.py", line 151, in setup
    self._wl = wandb_setup.setup()
  File "/home/kwangyeongill/anaconda/envs/FedSSL/lib/python3.9/site-packages/wandb/sdk/wandb_setup.py", line 320, in setup
    ret = _setup(settings=settings)
  File "/home/kwangyeongill/anaconda/envs/FedSSL/lib/python3.9/site-packages/wandb/sdk/wandb_setup.py", line 315, in _setup
    wl = _WandbSetup(settings=settings)
  File "/home/kwangyeongill/anaconda/envs/FedSSL/lib/python3.9/site-packages/wandb/sdk/wandb_setup.py", line 301, in __init__
    _WandbSetup._instance = _WandbSetup__WandbSetup(settings=settings, pid=pid)
  File "/home/kwangyeongill/anaconda/envs/FedSSL/lib/python3.9/site-packages/wandb/sdk/wandb_setup.py", line 114, in __init__
    self._setup()
  File "/home/kwangyeongill/anaconda/envs/FedSSL/lib/python3.9/site-packages/wandb/sdk/wandb_setup.py", line 242, in _setup
    self._setup_manager()
  File "/home/kwangyeongill/anaconda/envs/FedSSL/lib/python3.9/site-packages/wandb/sdk/wandb_setup.py", line 273, in _setup_manager
    self._manager = wandb_manager._Manager(
  File "/home/kwangyeongill/anaconda/envs/FedSSL/lib/python3.9/site-packages/wandb/sdk/wandb_manager.py", line 123, in __init__
    svc_iface._svc_connect(port=port)
  File "/home/kwangyeongill/anaconda/envs/FedSSL/lib/python3.9/site-packages/wandb/sdk/service/service_sock.py", line 31, in _svc_connect
    self._sock_client.connect(port=port)
  File "/home/kwangyeongill/anaconda/envs/FedSSL/lib/python3.9/site-packages/wandb/sdk/lib/sock_client.py", line 41, in connect
    s.connect(("localhost", port))
ConnectionRefusedError: [Errno 111] Connection refused

The above exception was the direct cause of the following exception:

Traceback (most recent call last):
  File "/home/kwangyeongill/anaconda/envs/FedSSL/lib/python3.9/multiprocessing/process.py", line 315, in _bootstrap
    self.run()
  File "/home/kwangyeongill/anaconda/envs/FedSSL/lib/python3.9/multiprocessing/process.py", line 108, in run
    self._target(*self._args, **self._kwargs)
  File "/home/kwangyeongill/FedSSL_clean/trainers.py", line 112, in train
    wandb_writer = wandb.init(
  File "/home/kwangyeongill/anaconda/envs/FedSSL/lib/python3.9/site-packages/wandb/sdk/wandb_init.py", line 1081, in init
    raise Exception("problem") from error_seen
Exception: problem
Traceback (most recent call last):
  File "/home/kwangyeongill/anaconda/envs/FedSSL/lib/python3.9/site-packages/wandb/sdk/wandb_init.py", line 1040, in init
    wi.setup(kwargs)
  File "/home/kwangyeongill/anaconda/envs/FedSSL/lib/python3.9/site-packages/wandb/sdk/wandb_init.py", line 151, in setup
    self._wl = wandb_setup.setup()
  File "/home/kwangyeongill/anaconda/envs/FedSSL/lib/python3.9/site-packages/wandb/sdk/wandb_setup.py", line 320, in setup
    ret = _setup(settings=settings)
  File "/home/kwangyeongill/anaconda/envs/FedSSL/lib/python3.9/site-packages/wandb/sdk/wandb_setup.py", line 315, in _setup
    wl = _WandbSetup(settings=settings)
  File "/home/kwangyeongill/anaconda/envs/FedSSL/lib/python3.9/site-packages/wandb/sdk/wandb_setup.py", line 301, in __init__
    _WandbSetup._instance = _WandbSetup__WandbSetup(settings=settings, pid=pid)
  File "/home/kwangyeongill/anaconda/envs/FedSSL/lib/python3.9/site-packages/wandb/sdk/wandb_setup.py", line 114, in __init__
    self._setup()
  File "/home/kwangyeongill/anaconda/envs/FedSSL/lib/python3.9/site-packages/wandb/sdk/wandb_setup.py", line 242, in _setup
    self._setup_manager()
  File "/home/kwangyeongill/anaconda/envs/FedSSL/lib/python3.9/site-packages/wandb/sdk/wandb_setup.py", line 273, in _setup_manager
    self._manager = wandb_manager._Manager(
  File "/home/kwangyeongill/anaconda/envs/FedSSL/lib/python3.9/site-packages/wandb/sdk/wandb_manager.py", line 123, in __init__
    svc_iface._svc_connect(port=port)
  File "/home/kwangyeongill/anaconda/envs/FedSSL/lib/python3.9/site-packages/wandb/sdk/service/service_sock.py", line 31, in _svc_connect
    self._sock_client.connect(port=port)
  File "/home/kwangyeongill/anaconda/envs/FedSSL/lib/python3.9/site-packages/wandb/sdk/lib/sock_client.py", line 41, in connect
    s.connect(("localhost", port))
ConnectionRefusedError: [Errno 111] Connection refused
wandb: ERROR Abnormal program exit
Process Process-5:
Traceback (most recent call last):
  File "/home/kwangyeongill/anaconda/envs/FedSSL/lib/python3.9/site-packages/wandb/sdk/wandb_init.py", line 1040, in init
    wi.setup(kwargs)
  File "/home/kwangyeongill/anaconda/envs/FedSSL/lib/python3.9/site-packages/wandb/sdk/wandb_init.py", line 151, in setup
    self._wl = wandb_setup.setup()
  File "/home/kwangyeongill/anaconda/envs/FedSSL/lib/python3.9/site-packages/wandb/sdk/wandb_setup.py", line 320, in setup
    ret = _setup(settings=settings)
  File "/home/kwangyeongill/anaconda/envs/FedSSL/lib/python3.9/site-packages/wandb/sdk/wandb_setup.py", line 315, in _setup
    wl = _WandbSetup(settings=settings)
  File "/home/kwangyeongill/anaconda/envs/FedSSL/lib/python3.9/site-packages/wandb/sdk/wandb_setup.py", line 301, in __init__
    _WandbSetup._instance = _WandbSetup__WandbSetup(settings=settings, pid=pid)
  File "/home/kwangyeongill/anaconda/envs/FedSSL/lib/python3.9/site-packages/wandb/sdk/wandb_setup.py", line 114, in __init__
    self._setup()
  File "/home/kwangyeongill/anaconda/envs/FedSSL/lib/python3.9/site-packages/wandb/sdk/wandb_setup.py", line 242, in _setup
    self._setup_manager()
  File "/home/kwangyeongill/anaconda/envs/FedSSL/lib/python3.9/site-packages/wandb/sdk/wandb_setup.py", line 273, in _setup_manager
    self._manager = wandb_manager._Manager(
  File "/home/kwangyeongill/anaconda/envs/FedSSL/lib/python3.9/site-packages/wandb/sdk/wandb_manager.py", line 123, in __init__
    svc_iface._svc_connect(port=port)
  File "/home/kwangyeongill/anaconda/envs/FedSSL/lib/python3.9/site-packages/wandb/sdk/service/service_sock.py", line 31, in _svc_connect
    self._sock_client.connect(port=port)
  File "/home/kwangyeongill/anaconda/envs/FedSSL/lib/python3.9/site-packages/wandb/sdk/lib/sock_client.py", line 41, in connect
    s.connect(("localhost", port))
ConnectionRefusedError: [Errno 111] Connection refused

The above exception was the direct cause of the following exception:

Traceback (most recent call last):
  File "/home/kwangyeongill/anaconda/envs/FedSSL/lib/python3.9/multiprocessing/process.py", line 315, in _bootstrap
    self.run()
  File "/home/kwangyeongill/anaconda/envs/FedSSL/lib/python3.9/multiprocessing/process.py", line 108, in run
    self._target(*self._args, **self._kwargs)
  File "/home/kwangyeongill/FedSSL_clean/trainers.py", line 112, in train
    wandb_writer = wandb.init(
  File "/home/kwangyeongill/anaconda/envs/FedSSL/lib/python3.9/site-packages/wandb/sdk/wandb_init.py", line 1081, in init
    raise Exception("problem") from error_seen
Exception: problem
Traceback (most recent call last):
  File "/home/kwangyeongill/anaconda/envs/FedSSL/lib/python3.9/site-packages/wandb/sdk/wandb_init.py", line 1040, in init
    wi.setup(kwargs)
  File "/home/kwangyeongill/anaconda/envs/FedSSL/lib/python3.9/site-packages/wandb/sdk/wandb_init.py", line 151, in setup
    self._wl = wandb_setup.setup()
  File "/home/kwangyeongill/anaconda/envs/FedSSL/lib/python3.9/site-packages/wandb/sdk/wandb_setup.py", line 320, in setup
    ret = _setup(settings=settings)
  File "/home/kwangyeongill/anaconda/envs/FedSSL/lib/python3.9/site-packages/wandb/sdk/wandb_setup.py", line 315, in _setup
    wl = _WandbSetup(settings=settings)
  File "/home/kwangyeongill/anaconda/envs/FedSSL/lib/python3.9/site-packages/wandb/sdk/wandb_setup.py", line 301, in __init__
    _WandbSetup._instance = _WandbSetup__WandbSetup(settings=settings, pid=pid)
  File "/home/kwangyeongill/anaconda/envs/FedSSL/lib/python3.9/site-packages/wandb/sdk/wandb_setup.py", line 114, in __init__
    self._setup()
  File "/home/kwangyeongill/anaconda/envs/FedSSL/lib/python3.9/site-packages/wandb/sdk/wandb_setup.py", line 242, in _setup
    self._setup_manager()
  File "/home/kwangyeongill/anaconda/envs/FedSSL/lib/python3.9/site-packages/wandb/sdk/wandb_setup.py", line 273, in _setup_manager
    self._manager = wandb_manager._Manager(
  File "/home/kwangyeongill/anaconda/envs/FedSSL/lib/python3.9/site-packages/wandb/sdk/wandb_manager.py", line 123, in __init__
    svc_iface._svc_connect(port=port)
  File "/home/kwangyeongill/anaconda/envs/FedSSL/lib/python3.9/site-packages/wandb/sdk/service/service_sock.py", line 31, in _svc_connect
    self._sock_client.connect(port=port)
  File "/home/kwangyeongill/anaconda/envs/FedSSL/lib/python3.9/site-packages/wandb/sdk/lib/sock_client.py", line 41, in connect
    s.connect(("localhost", port))
ConnectionRefusedError: [Errno 111] Connection refused
wandb: ERROR Abnormal program exit
Process Process-6:
Traceback (most recent call last):
  File "/home/kwangyeongill/anaconda/envs/FedSSL/lib/python3.9/site-packages/wandb/sdk/wandb_init.py", line 1040, in init
    wi.setup(kwargs)
  File "/home/kwangyeongill/anaconda/envs/FedSSL/lib/python3.9/site-packages/wandb/sdk/wandb_init.py", line 151, in setup
    self._wl = wandb_setup.setup()
  File "/home/kwangyeongill/anaconda/envs/FedSSL/lib/python3.9/site-packages/wandb/sdk/wandb_setup.py", line 320, in setup
    ret = _setup(settings=settings)
  File "/home/kwangyeongill/anaconda/envs/FedSSL/lib/python3.9/site-packages/wandb/sdk/wandb_setup.py", line 315, in _setup
    wl = _WandbSetup(settings=settings)
  File "/home/kwangyeongill/anaconda/envs/FedSSL/lib/python3.9/site-packages/wandb/sdk/wandb_setup.py", line 301, in __init__
    _WandbSetup._instance = _WandbSetup__WandbSetup(settings=settings, pid=pid)
  File "/home/kwangyeongill/anaconda/envs/FedSSL/lib/python3.9/site-packages/wandb/sdk/wandb_setup.py", line 114, in __init__
    self._setup()
  File "/home/kwangyeongill/anaconda/envs/FedSSL/lib/python3.9/site-packages/wandb/sdk/wandb_setup.py", line 242, in _setup
    self._setup_manager()
  File "/home/kwangyeongill/anaconda/envs/FedSSL/lib/python3.9/site-packages/wandb/sdk/wandb_setup.py", line 273, in _setup_manager
    self._manager = wandb_manager._Manager(
  File "/home/kwangyeongill/anaconda/envs/FedSSL/lib/python3.9/site-packages/wandb/sdk/wandb_manager.py", line 123, in __init__
    svc_iface._svc_connect(port=port)
  File "/home/kwangyeongill/anaconda/envs/FedSSL/lib/python3.9/site-packages/wandb/sdk/service/service_sock.py", line 31, in _svc_connect
    self._sock_client.connect(port=port)
  File "/home/kwangyeongill/anaconda/envs/FedSSL/lib/python3.9/site-packages/wandb/sdk/lib/sock_client.py", line 41, in connect
    s.connect(("localhost", port))
ConnectionRefusedError: [Errno 111] Connection refused

The above exception was the direct cause of the following exception:

Traceback (most recent call last):
  File "/home/kwangyeongill/anaconda/envs/FedSSL/lib/python3.9/multiprocessing/process.py", line 315, in _bootstrap
    self.run()
  File "/home/kwangyeongill/anaconda/envs/FedSSL/lib/python3.9/multiprocessing/process.py", line 108, in run
    self._target(*self._args, **self._kwargs)
  File "/home/kwangyeongill/FedSSL_clean/trainers.py", line 112, in train
    wandb_writer = wandb.init(
  File "/home/kwangyeongill/anaconda/envs/FedSSL/lib/python3.9/site-packages/wandb/sdk/wandb_init.py", line 1081, in init
    raise Exception("problem") from error_seen
Exception: problem
wandb: ERROR Error communicating with wandb process
wandb: ERROR For more info see: https://docs.wandb.ai/library/init#init-start-error
Process Process-2:
Traceback (most recent call last):
  File "/home/kwangyeongill/anaconda/envs/FedSSL/lib/python3.9/multiprocessing/process.py", line 315, in _bootstrap
    self.run()
  File "/home/kwangyeongill/anaconda/envs/FedSSL/lib/python3.9/multiprocessing/process.py", line 108, in run
    self._target(*self._args, **self._kwargs)
  File "/home/kwangyeongill/FedSSL_clean/trainers.py", line 112, in train
    wandb_writer = wandb.init(
  File "/home/kwangyeongill/anaconda/envs/FedSSL/lib/python3.9/site-packages/wandb/sdk/wandb_init.py", line 1043, in init
    run = wi.init()
  File "/home/kwangyeongill/anaconda/envs/FedSSL/lib/python3.9/site-packages/wandb/sdk/wandb_init.py", line 691, in init
    raise UsageError(error_message)
wandb.errors.UsageError: Error communicating with wandb process
For more info see: https://docs.wandb.ai/library/init#init-start-error
Problem at: /home/kwangyeongill/FedSSL_clean/trainers.py 112 train
Traceback (most recent call last):
  File "/home/kwangyeongill/anaconda/envs/FedSSL/lib/python3.9/site-packages/wandb/sdk/wandb_init.py", line 1040, in init
    wi.setup(kwargs)
  File "/home/kwangyeongill/anaconda/envs/FedSSL/lib/python3.9/site-packages/wandb/sdk/wandb_init.py", line 151, in setup
    self._wl = wandb_setup.setup()
  File "/home/kwangyeongill/anaconda/envs/FedSSL/lib/python3.9/site-packages/wandb/sdk/wandb_setup.py", line 320, in setup
    ret = _setup(settings=settings)
  File "/home/kwangyeongill/anaconda/envs/FedSSL/lib/python3.9/site-packages/wandb/sdk/wandb_setup.py", line 315, in _setup
    wl = _WandbSetup(settings=settings)
  File "/home/kwangyeongill/anaconda/envs/FedSSL/lib/python3.9/site-packages/wandb/sdk/wandb_setup.py", line 301, in __init__
    _WandbSetup._instance = _WandbSetup__WandbSetup(settings=settings, pid=pid)
  File "/home/kwangyeongill/anaconda/envs/FedSSL/lib/python3.9/site-packages/wandb/sdk/wandb_setup.py", line 114, in __init__
    self._setup()
  File "/home/kwangyeongill/anaconda/envs/FedSSL/lib/python3.9/site-packages/wandb/sdk/wandb_setup.py", line 242, in _setup
    self._setup_manager()
  File "/home/kwangyeongill/anaconda/envs/FedSSL/lib/python3.9/site-packages/wandb/sdk/wandb_setup.py", line 273, in _setup_manager
    self._manager = wandb_manager._Manager(
  File "/home/kwangyeongill/anaconda/envs/FedSSL/lib/python3.9/site-packages/wandb/sdk/wandb_manager.py", line 123, in __init__
    svc_iface._svc_connect(port=port)
  File "/home/kwangyeongill/anaconda/envs/FedSSL/lib/python3.9/site-packages/wandb/sdk/service/service_sock.py", line 31, in _svc_connect
    self._sock_client.connect(port=port)
  File "/home/kwangyeongill/anaconda/envs/FedSSL/lib/python3.9/site-packages/wandb/sdk/lib/sock_client.py", line 41, in connect
    s.connect(("localhost", port))
ConnectionRefusedError: [Errno 111] Connection refused
wandb: ERROR Abnormal program exit
Process Process-7:
Traceback (most recent call last):
  File "/home/kwangyeongill/anaconda/envs/FedSSL/lib/python3.9/site-packages/wandb/sdk/wandb_init.py", line 1040, in init
    wi.setup(kwargs)
  File "/home/kwangyeongill/anaconda/envs/FedSSL/lib/python3.9/site-packages/wandb/sdk/wandb_init.py", line 151, in setup
    self._wl = wandb_setup.setup()
  File "/home/kwangyeongill/anaconda/envs/FedSSL/lib/python3.9/site-packages/wandb/sdk/wandb_setup.py", line 320, in setup
    ret = _setup(settings=settings)
  File "/home/kwangyeongill/anaconda/envs/FedSSL/lib/python3.9/site-packages/wandb/sdk/wandb_setup.py", line 315, in _setup
    wl = _WandbSetup(settings=settings)
  File "/home/kwangyeongill/anaconda/envs/FedSSL/lib/python3.9/site-packages/wandb/sdk/wandb_setup.py", line 301, in __init__
    _WandbSetup._instance = _WandbSetup__WandbSetup(settings=settings, pid=pid)
  File "/home/kwangyeongill/anaconda/envs/FedSSL/lib/python3.9/site-packages/wandb/sdk/wandb_setup.py", line 114, in __init__
    self._setup()
  File "/home/kwangyeongill/anaconda/envs/FedSSL/lib/python3.9/site-packages/wandb/sdk/wandb_setup.py", line 242, in _setup
    self._setup_manager()
  File "/home/kwangyeongill/anaconda/envs/FedSSL/lib/python3.9/site-packages/wandb/sdk/wandb_setup.py", line 273, in _setup_manager
    self._manager = wandb_manager._Manager(
  File "/home/kwangyeongill/anaconda/envs/FedSSL/lib/python3.9/site-packages/wandb/sdk/wandb_manager.py", line 123, in __init__
    svc_iface._svc_connect(port=port)
  File "/home/kwangyeongill/anaconda/envs/FedSSL/lib/python3.9/site-packages/wandb/sdk/service/service_sock.py", line 31, in _svc_connect
    self._sock_client.connect(port=port)
  File "/home/kwangyeongill/anaconda/envs/FedSSL/lib/python3.9/site-packages/wandb/sdk/lib/sock_client.py", line 41, in connect
    s.connect(("localhost", port))
ConnectionRefusedError: [Errno 111] Connection refused

The above exception was the direct cause of the following exception:

Traceback (most recent call last):
  File "/home/kwangyeongill/anaconda/envs/FedSSL/lib/python3.9/multiprocessing/process.py", line 315, in _bootstrap
    self.run()
  File "/home/kwangyeongill/anaconda/envs/FedSSL/lib/python3.9/multiprocessing/process.py", line 108, in run
    self._target(*self._args, **self._kwargs)
  File "/home/kwangyeongill/FedSSL_clean/trainers.py", line 112, in train
    wandb_writer = wandb.init(
  File "/home/kwangyeongill/anaconda/envs/FedSSL/lib/python3.9/site-packages/wandb/sdk/wandb_init.py", line 1081, in init
    raise Exception("problem") from error_seen
Exception: problem
Traceback (most recent call last):
  File "/home/kwangyeongill/anaconda/envs/FedSSL/lib/python3.9/site-packages/wandb/sdk/wandb_init.py", line 1040, in init
    wi.setup(kwargs)
  File "/home/kwangyeongill/anaconda/envs/FedSSL/lib/python3.9/site-packages/wandb/sdk/wandb_init.py", line 151, in setup
    self._wl = wandb_setup.setup()
  File "/home/kwangyeongill/anaconda/envs/FedSSL/lib/python3.9/site-packages/wandb/sdk/wandb_setup.py", line 320, in setup
    ret = _setup(settings=settings)
  File "/home/kwangyeongill/anaconda/envs/FedSSL/lib/python3.9/site-packages/wandb/sdk/wandb_setup.py", line 315, in _setup
    wl = _WandbSetup(settings=settings)
  File "/home/kwangyeongill/anaconda/envs/FedSSL/lib/python3.9/site-packages/wandb/sdk/wandb_setup.py", line 301, in __init__
    _WandbSetup._instance = _WandbSetup__WandbSetup(settings=settings, pid=pid)
  File "/home/kwangyeongill/anaconda/envs/FedSSL/lib/python3.9/site-packages/wandb/sdk/wandb_setup.py", line 114, in __init__
    self._setup()
  File "/home/kwangyeongill/anaconda/envs/FedSSL/lib/python3.9/site-packages/wandb/sdk/wandb_setup.py", line 242, in _setup
    self._setup_manager()
  File "/home/kwangyeongill/anaconda/envs/FedSSL/lib/python3.9/site-packages/wandb/sdk/wandb_setup.py", line 273, in _setup_manager
    self._manager = wandb_manager._Manager(
  File "/home/kwangyeongill/anaconda/envs/FedSSL/lib/python3.9/site-packages/wandb/sdk/wandb_manager.py", line 123, in __init__
    svc_iface._svc_connect(port=port)
  File "/home/kwangyeongill/anaconda/envs/FedSSL/lib/python3.9/site-packages/wandb/sdk/service/service_sock.py", line 31, in _svc_connect
    self._sock_client.connect(port=port)
  File "/home/kwangyeongill/anaconda/envs/FedSSL/lib/python3.9/site-packages/wandb/sdk/lib/sock_client.py", line 41, in connect
    s.connect(("localhost", port))
ConnectionRefusedError: [Errno 111] Connection refused
wandb: ERROR Abnormal program exit
Process Process-8:
Traceback (most recent call last):
  File "/home/kwangyeongill/anaconda/envs/FedSSL/lib/python3.9/site-packages/wandb/sdk/wandb_init.py", line 1040, in init
    wi.setup(kwargs)
  File "/home/kwangyeongill/anaconda/envs/FedSSL/lib/python3.9/site-packages/wandb/sdk/wandb_init.py", line 151, in setup
    self._wl = wandb_setup.setup()
  File "/home/kwangyeongill/anaconda/envs/FedSSL/lib/python3.9/site-packages/wandb/sdk/wandb_setup.py", line 320, in setup
    ret = _setup(settings=settings)
  File "/home/kwangyeongill/anaconda/envs/FedSSL/lib/python3.9/site-packages/wandb/sdk/wandb_setup.py", line 315, in _setup
    wl = _WandbSetup(settings=settings)
  File "/home/kwangyeongill/anaconda/envs/FedSSL/lib/python3.9/site-packages/wandb/sdk/wandb_setup.py", line 301, in __init__
    _WandbSetup._instance = _WandbSetup__WandbSetup(settings=settings, pid=pid)
  File "/home/kwangyeongill/anaconda/envs/FedSSL/lib/python3.9/site-packages/wandb/sdk/wandb_setup.py", line 114, in __init__
    self._setup()
  File "/home/kwangyeongill/anaconda/envs/FedSSL/lib/python3.9/site-packages/wandb/sdk/wandb_setup.py", line 242, in _setup
    self._setup_manager()
  File "/home/kwangyeongill/anaconda/envs/FedSSL/lib/python3.9/site-packages/wandb/sdk/wandb_setup.py", line 273, in _setup_manager
    self._manager = wandb_manager._Manager(
  File "/home/kwangyeongill/anaconda/envs/FedSSL/lib/python3.9/site-packages/wandb/sdk/wandb_manager.py", line 123, in __init__
    svc_iface._svc_connect(port=port)
  File "/home/kwangyeongill/anaconda/envs/FedSSL/lib/python3.9/site-packages/wandb/sdk/service/service_sock.py", line 31, in _svc_connect
    self._sock_client.connect(port=port)
  File "/home/kwangyeongill/anaconda/envs/FedSSL/lib/python3.9/site-packages/wandb/sdk/lib/sock_client.py", line 41, in connect
    s.connect(("localhost", port))
ConnectionRefusedError: [Errno 111] Connection refused

The above exception was the direct cause of the following exception:

Traceback (most recent call last):
  File "/home/kwangyeongill/anaconda/envs/FedSSL/lib/python3.9/multiprocessing/process.py", line 315, in _bootstrap
    self.run()
  File "/home/kwangyeongill/anaconda/envs/FedSSL/lib/python3.9/multiprocessing/process.py", line 108, in run
    self._target(*self._args, **self._kwargs)
  File "/home/kwangyeongill/FedSSL_clean/trainers.py", line 112, in train
    wandb_writer = wandb.init(
  File "/home/kwangyeongill/anaconda/envs/FedSSL/lib/python3.9/site-packages/wandb/sdk/wandb_init.py", line 1081, in init
    raise Exception("problem") from error_seen
Exception: problem
Traceback (most recent call last):
  File "/home/kwangyeongill/anaconda/envs/FedSSL/lib/python3.9/site-packages/wandb/sdk/wandb_init.py", line 1040, in init
    wi.setup(kwargs)
  File "/home/kwangyeongill/anaconda/envs/FedSSL/lib/python3.9/site-packages/wandb/sdk/wandb_init.py", line 151, in setup
    self._wl = wandb_setup.setup()
  File "/home/kwangyeongill/anaconda/envs/FedSSL/lib/python3.9/site-packages/wandb/sdk/wandb_setup.py", line 320, in setup
    ret = _setup(settings=settings)
  File "/home/kwangyeongill/anaconda/envs/FedSSL/lib/python3.9/site-packages/wandb/sdk/wandb_setup.py", line 315, in _setup
    wl = _WandbSetup(settings=settings)
  File "/home/kwangyeongill/anaconda/envs/FedSSL/lib/python3.9/site-packages/wandb/sdk/wandb_setup.py", line 301, in __init__
    _WandbSetup._instance = _WandbSetup__WandbSetup(settings=settings, pid=pid)
  File "/home/kwangyeongill/anaconda/envs/FedSSL/lib/python3.9/site-packages/wandb/sdk/wandb_setup.py", line 114, in __init__
    self._setup()
  File "/home/kwangyeongill/anaconda/envs/FedSSL/lib/python3.9/site-packages/wandb/sdk/wandb_setup.py", line 242, in _setup
    self._setup_manager()
  File "/home/kwangyeongill/anaconda/envs/FedSSL/lib/python3.9/site-packages/wandb/sdk/wandb_setup.py", line 273, in _setup_manager
    self._manager = wandb_manager._Manager(
  File "/home/kwangyeongill/anaconda/envs/FedSSL/lib/python3.9/site-packages/wandb/sdk/wandb_manager.py", line 123, in __init__
    svc_iface._svc_connect(port=port)
  File "/home/kwangyeongill/anaconda/envs/FedSSL/lib/python3.9/site-packages/wandb/sdk/service/service_sock.py", line 31, in _svc_connect
    self._sock_client.connect(port=port)
  File "/home/kwangyeongill/anaconda/envs/FedSSL/lib/python3.9/site-packages/wandb/sdk/lib/sock_client.py", line 41, in connect
    s.connect(("localhost", port))
ConnectionRefusedError: [Errno 111] Connection refused
wandb: ERROR Abnormal program exit
Process Process-9:
Traceback (most recent call last):
  File "/home/kwangyeongill/anaconda/envs/FedSSL/lib/python3.9/site-packages/wandb/sdk/wandb_init.py", line 1040, in init
    wi.setup(kwargs)
  File "/home/kwangyeongill/anaconda/envs/FedSSL/lib/python3.9/site-packages/wandb/sdk/wandb_init.py", line 151, in setup
    self._wl = wandb_setup.setup()
  File "/home/kwangyeongill/anaconda/envs/FedSSL/lib/python3.9/site-packages/wandb/sdk/wandb_setup.py", line 320, in setup
    ret = _setup(settings=settings)
  File "/home/kwangyeongill/anaconda/envs/FedSSL/lib/python3.9/site-packages/wandb/sdk/wandb_setup.py", line 315, in _setup
    wl = _WandbSetup(settings=settings)
  File "/home/kwangyeongill/anaconda/envs/FedSSL/lib/python3.9/site-packages/wandb/sdk/wandb_setup.py", line 301, in __init__
    _WandbSetup._instance = _WandbSetup__WandbSetup(settings=settings, pid=pid)
  File "/home/kwangyeongill/anaconda/envs/FedSSL/lib/python3.9/site-packages/wandb/sdk/wandb_setup.py", line 114, in __init__
    self._setup()
  File "/home/kwangyeongill/anaconda/envs/FedSSL/lib/python3.9/site-packages/wandb/sdk/wandb_setup.py", line 242, in _setup
    self._setup_manager()
  File "/home/kwangyeongill/anaconda/envs/FedSSL/lib/python3.9/site-packages/wandb/sdk/wandb_setup.py", line 273, in _setup_manager
    self._manager = wandb_manager._Manager(
  File "/home/kwangyeongill/anaconda/envs/FedSSL/lib/python3.9/site-packages/wandb/sdk/wandb_manager.py", line 123, in __init__
    svc_iface._svc_connect(port=port)
  File "/home/kwangyeongill/anaconda/envs/FedSSL/lib/python3.9/site-packages/wandb/sdk/service/service_sock.py", line 31, in _svc_connect
    self._sock_client.connect(port=port)
  File "/home/kwangyeongill/anaconda/envs/FedSSL/lib/python3.9/site-packages/wandb/sdk/lib/sock_client.py", line 41, in connect
    s.connect(("localhost", port))
ConnectionRefusedError: [Errno 111] Connection refused

The above exception was the direct cause of the following exception:

Traceback (most recent call last):
  File "/home/kwangyeongill/anaconda/envs/FedSSL/lib/python3.9/multiprocessing/process.py", line 315, in _bootstrap
    self.run()
  File "/home/kwangyeongill/anaconda/envs/FedSSL/lib/python3.9/multiprocessing/process.py", line 108, in run
    self._target(*self._args, **self._kwargs)
  File "/home/kwangyeongill/FedSSL_clean/trainers.py", line 112, in train
    wandb_writer = wandb.init(
  File "/home/kwangyeongill/anaconda/envs/FedSSL/lib/python3.9/site-packages/wandb/sdk/wandb_init.py", line 1081, in init
    raise Exception("problem") from error_seen
Exception: problem
Traceback (most recent call last):
  File "/home/kwangyeongill/anaconda/envs/FedSSL/lib/python3.9/site-packages/wandb/sdk/wandb_init.py", line 1040, in init
    wi.setup(kwargs)
  File "/home/kwangyeongill/anaconda/envs/FedSSL/lib/python3.9/site-packages/wandb/sdk/wandb_init.py", line 151, in setup
    self._wl = wandb_setup.setup()
  File "/home/kwangyeongill/anaconda/envs/FedSSL/lib/python3.9/site-packages/wandb/sdk/wandb_setup.py", line 320, in setup
    ret = _setup(settings=settings)
  File "/home/kwangyeongill/anaconda/envs/FedSSL/lib/python3.9/site-packages/wandb/sdk/wandb_setup.py", line 315, in _setup
    wl = _WandbSetup(settings=settings)
  File "/home/kwangyeongill/anaconda/envs/FedSSL/lib/python3.9/site-packages/wandb/sdk/wandb_setup.py", line 301, in __init__
    _WandbSetup._instance = _WandbSetup__WandbSetup(settings=settings, pid=pid)
  File "/home/kwangyeongill/anaconda/envs/FedSSL/lib/python3.9/site-packages/wandb/sdk/wandb_setup.py", line 114, in __init__
    self._setup()
  File "/home/kwangyeongill/anaconda/envs/FedSSL/lib/python3.9/site-packages/wandb/sdk/wandb_setup.py", line 242, in _setup
    self._setup_manager()
  File "/home/kwangyeongill/anaconda/envs/FedSSL/lib/python3.9/site-packages/wandb/sdk/wandb_setup.py", line 273, in _setup_manager
    self._manager = wandb_manager._Manager(
  File "/home/kwangyeongill/anaconda/envs/FedSSL/lib/python3.9/site-packages/wandb/sdk/wandb_manager.py", line 123, in __init__
    svc_iface._svc_connect(port=port)
  File "/home/kwangyeongill/anaconda/envs/FedSSL/lib/python3.9/site-packages/wandb/sdk/service/service_sock.py", line 31, in _svc_connect
    self._sock_client.connect(port=port)
  File "/home/kwangyeongill/anaconda/envs/FedSSL/lib/python3.9/site-packages/wandb/sdk/lib/sock_client.py", line 41, in connect
    s.connect(("localhost", port))
ConnectionRefusedError: [Errno 111] Connection refused
wandb: ERROR Abnormal program exit
Process Process-10:
Traceback (most recent call last):
  File "/home/kwangyeongill/anaconda/envs/FedSSL/lib/python3.9/site-packages/wandb/sdk/wandb_init.py", line 1040, in init
    wi.setup(kwargs)
  File "/home/kwangyeongill/anaconda/envs/FedSSL/lib/python3.9/site-packages/wandb/sdk/wandb_init.py", line 151, in setup
    self._wl = wandb_setup.setup()
  File "/home/kwangyeongill/anaconda/envs/FedSSL/lib/python3.9/site-packages/wandb/sdk/wandb_setup.py", line 320, in setup
    ret = _setup(settings=settings)
  File "/home/kwangyeongill/anaconda/envs/FedSSL/lib/python3.9/site-packages/wandb/sdk/wandb_setup.py", line 315, in _setup
    wl = _WandbSetup(settings=settings)
  File "/home/kwangyeongill/anaconda/envs/FedSSL/lib/python3.9/site-packages/wandb/sdk/wandb_setup.py", line 301, in __init__
    _WandbSetup._instance = _WandbSetup__WandbSetup(settings=settings, pid=pid)
  File "/home/kwangyeongill/anaconda/envs/FedSSL/lib/python3.9/site-packages/wandb/sdk/wandb_setup.py", line 114, in __init__
    self._setup()
  File "/home/kwangyeongill/anaconda/envs/FedSSL/lib/python3.9/site-packages/wandb/sdk/wandb_setup.py", line 242, in _setup
    self._setup_manager()
  File "/home/kwangyeongill/anaconda/envs/FedSSL/lib/python3.9/site-packages/wandb/sdk/wandb_setup.py", line 273, in _setup_manager
    self._manager = wandb_manager._Manager(
  File "/home/kwangyeongill/anaconda/envs/FedSSL/lib/python3.9/site-packages/wandb/sdk/wandb_manager.py", line 123, in __init__
    svc_iface._svc_connect(port=port)
  File "/home/kwangyeongill/anaconda/envs/FedSSL/lib/python3.9/site-packages/wandb/sdk/service/service_sock.py", line 31, in _svc_connect
    self._sock_client.connect(port=port)
  File "/home/kwangyeongill/anaconda/envs/FedSSL/lib/python3.9/site-packages/wandb/sdk/lib/sock_client.py", line 41, in connect
    s.connect(("localhost", port))
ConnectionRefusedError: [Errno 111] Connection refused

The above exception was the direct cause of the following exception:

Traceback (most recent call last):
  File "/home/kwangyeongill/anaconda/envs/FedSSL/lib/python3.9/multiprocessing/process.py", line 315, in _bootstrap
    self.run()
  File "/home/kwangyeongill/anaconda/envs/FedSSL/lib/python3.9/multiprocessing/process.py", line 108, in run
    self._target(*self._args, **self._kwargs)
  File "/home/kwangyeongill/FedSSL_clean/trainers.py", line 112, in train
    wandb_writer = wandb.init(
  File "/home/kwangyeongill/anaconda/envs/FedSSL/lib/python3.9/site-packages/wandb/sdk/wandb_init.py", line 1081, in init
    raise Exception("problem") from error_seen
Exception: problem
slurmstepd: error: *** JOB 169131 ON b02 CANCELLED AT 2022-08-10T20:46:11 ***
